Workbook

Sheet Prodotti Finiti
A1: Prodotto | B1: Prezzo Vendita (€) | C1: Costo Totale al Pezzo (€) | D1: Piadina / Pane (€) | E1: Carne (€) | F1: Cottura + Verdure (€) | G1: Salume/Crudo/Cotto (€) | H1: Formaggio (€) | I1: Fritto surgelato (€) | J1: Olio (€) | K1: Condimenti (€) | L1: Stecchini (€) | M1: Piatto (€) | N1: Tovagliolo (€) | O1: Bevanda (€) | P1: Bicchiere (€) | Q1: Liquore (€) | R1: Ghiaccio (€) | S1: CO2 (€) | T1: Margine (€) | U1: Margine (%) | V1: Nome a menu | W1: Descrizione a menu
A2: PIADINA P.CRUDO | B2: 5.5 | C2: =SUM(D2:S2) -> 2.1613154 | D2: ='Prezzi Unitari'!$E$6 -> 0.6552 | G2: =Parametri!$B$4/100*'Prezzi Unitari'!$E$9 -> 1.4135 | M2: ='Prezzi Unitari'!$E$12 -> 0.058804 | N2: ='Prezzi Unitari'!$E$11 -> 0.033811429 | T2: =B2-C2 -> 3.3386846 | U2: =T2/B2 -> 0.60703356 | V2: Piadina prosciutto crudo
A3: PIADINA P.CRUDO E FORMAGGIO | B3: 5.5 | C3: =SUM(D3:S3) -> 2.0233754 | D3: ='Prezzi Unitari'!$E$6 -> 0.6552 | G3: =Parametri!$B$5/100*'Prezzi Unitari'!$E$9 -> 1.1308 | H3: =Parametri!$B$6/100*'Prezzi Unitari'!$E$7 -> 0.14476 | M3: ='Prezzi Unitari'!$E$12 -> 0.058804 | N3: ='Prezzi Unitari'!$E$11 -> 0.033811429 | T3: =B3-C3 -> 3.4766246 | U3: =T3/B3 -> 0.63211356 | V3: Piadina prosciutto crudo e formaggio
A4: PIADINA P.COTTO | B4: 5 | C4: =SUM(D4:S4) -> 1.8918154 | D4: ='Prezzi Unitari'!$E$6 -> 0.6552 | G4: =Parametri!$B$4/100*'Prezzi Unitari'!$E$5 -> 1.144 | M4: ='Prezzi Unitari'!$E$12 -> 0.058804 | N4: ='Prezzi Unitari'!$E$11 -> 0.033811429 | T4: =B4-C4 -> 3.1081846 | U4: =T4/B4 -> 0.62163691 | V4: Piadina prosciutto cotto
A5: PIADINA P.COTTO E FORMAGGIO | B5: 5 | C5: =SUM(D5:S5) -> 1.8077754 | D5: ='Prezzi Unitari'!$E$6 -> 0.6552 | G5: =Parametri!$B$5/100*'Prezzi Unitari'!$E$5 -> 0.9152 | H5: =Parametri!$B$6/100*'Prezzi Unitari'!$E$7 -> 0.14476 | M5: ='Prezzi Unitari'!$E$12 -> 0.058804 | N5: ='Prezzi Unitari'!$E$11 -> 0.033811429 | T5: =B5-C5 -> 3.1922246 | U5: =T5/B5 -> 0.63844491 | V5: Piadina prosciutto cotto e formaggio
A6: PIADINA SALAME | B6: 5.5 | C6: =SUM(D6:S6) -> 2.1668154 | D6: ='Prezzi Unitari'!$E$6 -> 0.6552 | G6: =Parametri!$B$4/100*'Prezzi Unitari'!$E$8 -> 1.419 | M6: ='Prezzi Unitari'!$E$12 -> 0.058804 | N6: ='Prezzi Unitari'!$E$11 -> 0.033811429 | T6: =B6-C6 -> 3.3331846 | U6: =T6/B6 -> 0.60603356 | V6: Piadina salame ferrarese
A7: PIADINA SALAME E FORMAGGIO | B7: 5.5 | C7: =SUM(D7:S7) -> 2.0277754 | D7: ='Prezzi Unitari'!$E$6 -> 0.6552 | G7: =Parametri!$B$5/100*'Prezzi Unitari'!$E$8 -> 1.1352 | H7: =Parametri!$B$6/100*'Prezzi Unitari'!$E$7 -> 0.14476 | M7: ='Prezzi Unitari'!$E$12 -> 0.058804 | N7: ='Prezzi Unitari'!$E$11 -> 0.033811429 | T7: =B7-C7 -> 3.4722246 | U7: =T7/B7 -> 0.63131356 | V7: Piadina salame ferrarese e formaggio
A8: PIADINA SOLO FORMAGGIO | B8: 5 | C8: =SUM(D8:S8) -> 1.4716154 | D8: ='Prezzi Unitari'!$E$6 -> 0.6552 | H8: =Parametri!$B$7/100*'Prezzi Unitari'!$E$7 -> 0.7238 | M8: ='Prezzi Unitari'!$E$12 -> 0.058804 | N8: ='Prezzi Unitari'!$E$11 -> 0.033811429 | T8: =B8-C8 -> 3.5283846 | U8: =T8/B8 -> 0.70567691 | V8: Piadina solo formaggio
A9: HAMBURGER CON PATATINE | B9: 9.5 | C9: =SUM(D9:S9) -> 3.9524675 | D9: ='Prezzi Unitari'!$E$10 -> 0.3146 | E9: =Parametri!$B$44 -> 1.5 | F9: =Parametri!$B$47 -> 1 | H9: =Parametri!$B$48/100*'Prezzi Unitari'!$E$7 -> 0.14476 | I9: =Parametri!$B$78/1000*'Materie Prime IperTosano'!$H$4 -> 0.312 | J9: =Parametri!$B$78*Parametri!$B$79/0.92/1000*'Prezzi Unitari'!$E$2 -> 0.062458696 | K9: =Parametri!$B$82*'Prezzi Unitari'!$E$3+Parametri!$B$83*'Prezzi Unitari'!$E$4 -> 0.37339394 | L9: =Parametri!$B$84*'Prezzi Unitari'!$E$13 -> 0.060024 | M9: =Parametri!$B$80*'Prezzi Unitari'!$E$12 -> 0.117608 | N9: =Parametri!$B$81*'Prezzi Unitari'!$E$11 -> 0.067622857 | T9: =B9-C9 -> 5.5475325 | U9: =T9/B9 -> 0.58395079 | V9: Piatto hamburger | W9: Carne del macellaio, pomodoro, insalata, maionese e ketchup, con patatine fritte
A10: PATATINE FRITTE | B10: 3 | C10: =SUM(D10:S10) -> 0.69378709 | I10: =Parametri!$B$9/1000*'Materie Prime IperTosano'!$H$4 -> 0.312 | J10: =Parametri!$B$12/1000*'Prezzi Unitari'!$E$2 -> 0.062458696 | K10: =Parametri!$B$15*'Prezzi Unitari'!$E$3+Parametri!$B$16*'Prezzi Unitari'!$E$4 -> 0.18669697 | L10: =Parametri!$B$17*'Prezzi Unitari'!$E$13 -> 0.040016 | M10: =Parametri!$B$13*'Prezzi Unitari'!$E$12 -> 0.058804 | N10: =Parametri!$B$14*'Prezzi Unitari'!$E$11 -> 0.033811429 | T10: =B10-C10 -> 2.3062129 | U10: =T10/B10 -> 0.76873764 | V10: Patatine fritte | W10: Con ketchup e maionese
A11: ACQUA NATURALE 0,5L | B11: 1 | C11: =SUM(D11:S11) -> 0.13333333 | O11: ='Materie Prime IperTosano'!$H$2 -> 0.13333333 | T11: =B11-C11 -> 0.86666667 | U11: =T11/B11 -> 0.86666667 | V11: Acqua naturale | W11: Bottiglia 0,5 L
A12: ACQUA FRIZZANTE 0,5L | B12: 1 | C12: =SUM(D12:S12) -> 0.13333333 | O12: ='Materie Prime IperTosano'!$H$3 -> 0.13333333 | T12: =B12-C12 -> 0.86666667 | U12: =T12/B12 -> 0.86666667 | V12: Acqua frizzante | W12: Bottiglia 0,5 L
A13: COCA COLA 0,2L | B13: 2.5 | C13: =SUM(D13:S13) -> 0.78135155 | O13: =0.2*'Materie Prime Bevande'!$I$5 -> 0.57706 | P13: ='Materie Prime Bevande'!$I$6 -> 0.09638 | S13: =0.2*Parametri!$B$35 -> 0.10791155 | T13: =B13-C13 -> 1.7186485 | U13: =T13/B13 -> 0.68745938 | V13: Coca Cola | W13: Alla spina
A14: COCA COLA 0,4L | B14: 4 | C14: =SUM(D14:S14) -> 1.5004831 | O14: =0.4*'Materie Prime Bevande'!$I$5 -> 1.15412 | P14: ='Materie Prime Bevande'!$I$7 -> 0.13054 | S14: =0.4*Parametri!$B$35 -> 0.2158231 | T14: =B14-C14 -> 2.4995169 | U14: =T14/B14 -> 0.62487923
A15: SPRITE 0,33L | B15: 2 | C15: =SUM(D15:S15) -> 0.79259333 | O15: ='Materie Prime Bevande'!$I$13 -> 0.67913333 | P15: ='Materie Prime Bevande'!$I$10 -> 0.11346 | T15: =B15-C15 -> 1.2074067 | U15: =T15/B15 -> 0.60370333 | V15: Sprite | W15: Lattina 0,33 L
A16: COCA COLA SENZA CAFFEINA 0,33L | B16: 2 | C16: =SUM(D16:S16) -> 0.79259333 | O16: ='Materie Prime Bevande'!$I$14 -> 0.67913333 | P16: ='Materie Prime Bevande'!$I$10 -> 0.11346 | T16: =B16-C16 -> 1.2074067 | U16: =T16/B16 -> 0.60370333 | V16: Coca Cola senza caffeina | W16: Lattina 0,33 L
A17: THE LIMONE | B17: 2 | C17: =SUM(D17:S17) -> 0.79259333 | O17: ='Materie Prime Bevande'!$I$8 -> 0.67913333 | P17: ='Materie Prime Bevande'!$I$10 -> 0.11346 | T17: =B17-C17 -> 1.2074067 | U17: =T17/B17 -> 0.60370333 | V17: Tè al limone | W17: Lattina 0,33 L
A18: THE PESCA | B18: 2 | C18: =SUM(D18:S18) -> 0.79259333 | O18: ='Materie Prime Bevande'!$I$9 -> 0.67913333 | P18: ='Materie Prime Bevande'!$I$10 -> 0.11346 | T18: =B18-C18 -> 1.2074067 | U18: =T18/B18 -> 0.60370333 | V18: Tè alla pesca | W18: Lattina 0,33 L
A19: BIRRA ROSSA 0,2L | B19: 3 | C19: =SUM(D19:S19) -> 1.0468092 | O19: =0.2*'Materie Prime Bevande'!$I$3 -> 0.84251765 | P19: ='Materie Prime Bevande'!$I$6 -> 0.09638 | S19: =0.2*Parametri!$B$35 -> 0.10791155 | T19: =B19-C19 -> 1.9531908 | U19: =T19/B19 -> 0.6510636 | V19: Birra rossa | W19: Alla spina
A20: BIRRA ROSSA 0,4L | B20: 5 | C20: =SUM(D20:S20) -> 2.0313984 | O20: =0.4*'Materie Prime Bevande'!$I$3 -> 1.6850353 | P20: ='Materie Prime Bevande'!$I$7 -> 0.13054 | S20: =0.4*Parametri!$B$35 -> 0.2158231 | T20: =B20-C20 -> 2.9686016 | U20: =T20/B20 -> 0.59372032
A21: BIRRA BIONDA 0,2L | B21: 2.5 | C21: =SUM(D21:S21) -> 0.90810955 | O21: =0.2*'Materie Prime Bevande'!$I$2 -> 0.703818 | P21: ='Materie Prime Bevande'!$I$6 -> 0.09638 | S21: =0.2*Parametri!$B$35 -> 0.10791155 | T21: =B21-C21 -> 1.5918905 | U21: =T21/B21 -> 0.63675618 | V21: Birra bionda | W21: Alla spina
A22: BIRRA BIONDA 0,4L | B22: 4 | C22: =SUM(D22:S22) -> 1.7539991 | O22: =0.4*'Materie Prime Bevande'!$I$2 -> 1.407636 | P22: ='Materie Prime Bevande'!$I$7 -> 0.13054 | S22: =0.4*Parametri!$B$35 -> 0.2158231 | T22: =B22-C22 -> 2.2460009 | U22: =T22/B22 -> 0.56150023
A23: VINO BIANCO 0,2L | B23: 2.5 | C23: =SUM(D23:S23) -> 0.83410435 | O23: =0.2*'Materie Prime Bevande'!$I$4 -> 0.6298128 | P23: ='Materie Prime Bevande'!$I$6 -> 0.09638 | S23: =0.2*Parametri!$B$35 -> 0.10791155 | T23: =B23-C23 -> 1.6658957 | U23: =T23/B23 -> 0.66635826 | V23: Vino bianco frizzante | W23: Alla spina
A24: SPRITZ APEROL | B24: 3.5 | C24: =SUM(D24:S24) -> 1.4013825 | O24: =Parametri!$B$27/1000*'Materie Prime Bevande'!$I$4 -> 0.3673908 | P24: ='Materie Prime Bevande'!$I$10 -> 0.11346 | Q24: =Parametri!$B$28/1000*'Materie Prime Bevande'!$I$11 -> 0.78283333 | R24: =Parametri!$B$29/1000*'Materie Prime IperTosano'!$H$5 -> 0.07475 | S24: =Parametri!$B$27/1000*Parametri!$B$35 -> 0.062948403 | T24: =B24-C24 -> 2.0986175 | U24: =T24/B24 -> 0.59960499 | V24: Spritz Aperol
A25: SPRITZ CAMPARI | B25: 3.5 | C25: =SUM(D25:S25) -> 1.6219992 | O25: =Parametri!$B$27/1000*'Materie Prime Bevande'!$I$4 -> 0.3673908 | P25: ='Materie Prime Bevande'!$I$10 -> 0.11346 | Q25: =Parametri!$B$28/1000*'Materie Prime Bevande'!$I$12 -> 1.00345 | R25: =Parametri!$B$29/1000*'Materie Prime IperTosano'!$H$5 -> 0.07475 | S25: =Parametri!$B$27/1000*Parametri!$B$35 -> 0.062948403 | T25: =B25-C25 -> 1.8780008 | U25: =T25/B25 -> 0.53657166 | V25: Spritz Campari
A26: ANELLI DI CIPOLLA | B26: 3.5 | C26: =SUM(D26:S26) -> 1.1818036 | I26: =Parametri!$B$56/1000*'Materie Prime IperTosano'!$H$6 -> 0.825 | J26: =Parametri!$B$56*Parametri!$B$57/0.92/1000*'Prezzi Unitari'!$E$2 -> 0.037475217 | K26: =Parametri!$B$60*'Prezzi Unitari'!$E$3+Parametri!$B$61*'Prezzi Unitari'!$E$4 -> 0.18669697 | L26: =Parametri!$B$62*'Prezzi Unitari'!$E$13 -> 0.040016 | M26: =Parametri!$B$58*'Prezzi Unitari'!$E$12 -> 0.058804 | N26: =Parametri!$B$59*'Prezzi Unitari'!$E$11 -> 0.033811429 | T26: =B26-C26 -> 2.3181964 | U26: =T26/B26 -> 0.66234182
A27: OLIVE ALL'ASCOLANA | B27: 3.5 | C27: =SUM(D27:S27) -> 1.2602861 | I27: =Parametri!$B$65/1000*'Materie Prime IperTosano'!$H$7 -> 0.987 | J27: =Parametri!$B$65*Parametri!$B$66/0.92/1000*'Prezzi Unitari'!$E$2 -> 0.046844022 | K27: =Parametri!$B$69*'Prezzi Unitari'!$E$3+Parametri!$B$70*'Prezzi Unitari'!$E$4 -> 0.093810606 | L27: =Parametri!$B$71*'Prezzi Unitari'!$E$13 -> 0.040016 | M27: =Parametri!$B$67*'Prezzi Unitari'!$E$12 -> 0.058804 | N27: =Parametri!$B$68*'Prezzi Unitari'!$E$11 -> 0.033811429 | T27: =B27-C27 -> 2.2397139 | U27: =T27/B27 -> 0.63991827
A29: Verde = prezzo impostato per il 2026. Composizioni e grammature nel foglio 'Parametri'. Righe GRIGIE = prodotti valutati ma NON a menu 2026 (i costi restano calcolati). Le colonne V e W (beige) alimentano il menu HTML: modificandole cambia il testo del menu.

Sheet Margine 2025
A1: Prodotto | B1: Pezzi Venduti 2025 | C1: Prezzo Vendita Attuale (€) | D1: Incasso Previsto (€) | E1: Costo Unitario (€) | F1: Costo Totale (€) | G1: Margine Totale (€) | H1: % su Margine Complessivo
A2: PIADINA P.CRUDO | B2: ='Vendite 2025'!$F$13 -> 63 | C2: ='Prodotti Finiti'!$B$2 -> 5.5 | D2: =B2*C2 -> 346.5 | E2: ='Prodotti Finiti'!$C$2 -> 2.1613154 | F2: =B2*E2 -> 136.16287 | G2: =D2-F2 -> 210.33713 | H2: =IF($G$28=0,"",G2/$G$28) -> 0.05223912
A3: PIADINA P.CRUDO E FORMAGGIO | B3: ='Vendite 2025'!$F$14 -> 133 | C3: ='Prodotti Finiti'!$B$3 -> 5.5 | D3: =B3*C3 -> 731.5 | E3: ='Prodotti Finiti'!$C$3 -> 2.0233754 | F3: =B3*E3 -> 269.10893 | G3: =D3-F3 -> 462.39107 | H3: =IF($G$28=0,"",G3/$G$28) -> 0.11483898
A4: PIADINA P.COTTO | B4: ='Vendite 2025'!$F$11 -> 66 | C4: ='Prodotti Finiti'!$B$4 -> 5 | D4: =B4*C4 -> 330 | E4: ='Prodotti Finiti'!$C$4 -> 1.8918154 | F4: =B4*E4 -> 124.85982 | G4: =D4-F4 -> 205.14018 | H4: =IF($G$28=0,"",G4/$G$28) -> 0.050948411
A5: PIADINA P.COTTO E FORMAGGIO | B5: ='Vendite 2025'!$F$12 -> 128 | C5: ='Prodotti Finiti'!$B$5 -> 5 | D5: =B5*C5 -> 640 | E5: ='Prodotti Finiti'!$C$5 -> 1.8077754 | F5: =B5*E5 -> 231.39525 | G5: =D5-F5 -> 408.60475 | H5: =IF($G$28=0,"",G5/$G$28) -> 0.10148067
A6: PIADINA SALAME | B6: ='Vendite 2025'!$F$15 -> 35 | C6: ='Prodotti Finiti'!$B$6 -> 5.5 | D6: =B6*C6 -> 192.5 | E6: ='Prodotti Finiti'!$C$6 -> 2.1668154 | F6: =B6*E6 -> 75.83854 | G6: =D6-F6 -> 116.66146 | H6: =IF($G$28=0,"",G6/$G$28) -> 0.028973924
A7: PIADINA SALAME E FORMAGGIO | B7: ='Vendite 2025'!$F$16 -> 90 | C7: ='Prodotti Finiti'!$B$7 -> 5.5 | D7: =B7*C7 -> 495 | E7: ='Prodotti Finiti'!$C$7 -> 2.0277754 | F7: =B7*E7 -> 182.49979 | G7: =D7-F7 -> 312.50021 | H7: =IF($G$28=0,"",G7/$G$28) -> 0.077612241
A8: PIADINA SOLO FORMAGGIO | B8: ='Vendite 2025'!$F$17 -> 15 | C8: ='Prodotti Finiti'!$B$8 -> 5 | D8: =B8*C8 -> 75 | E8: ='Prodotti Finiti'!$C$8 -> 1.4716154 | F8: =B8*E8 -> 22.074231 | G8: =D8-F8 -> 52.925769 | H8: =IF($G$28=0,"",G8/$G$28) -> 0.013144591
A9: HAMBURGER CON PATATINE | B9: 0 | C9: ='Prodotti Finiti'!$B$9 -> 9.5 | D9: =B9*C9 -> 0 | E9: ='Prodotti Finiti'!$C$9 -> 3.9524675 | F9: =B9*E9 -> 0 | G9: =D9-F9 -> 0 | H9: =IF($G$28=0,"",G9/$G$28) -> 0
A10: PATATINE FRITTE | B10: ='Vendite 2025'!$F$10 -> 341 | C10: ='Prodotti Finiti'!$B$10 -> 3 | D10: =B10*C10 -> 1023 | E10: ='Prodotti Finiti'!$C$10 -> 0.69378709 | F10: =B10*E10 -> 236.5814 | G10: =D10-F10 -> 786.4186 | H10: =IF($G$28=0,"",G10/$G$28) -> 0.19531414
A11: ACQUA NATURALE 0,5L | B11: ='Vendite 2025'!$F$3 -> 206 | C11: ='Prodotti Finiti'!$B$11 -> 1 | D11: =B11*C11 -> 206 | E11: ='Prodotti Finiti'!$C$11 -> 0.13333333 | F11: =B11*E11 -> 27.466667 | G11: =D11-F11 -> 178.53333 | H11: =IF($G$28=0,"",G11/$G$28) -> 0.044340361
A12: ACQUA FRIZZANTE 0,5L | B12: ='Vendite 2025'!$F$2 -> 62 | C12: ='Prodotti Finiti'!$B$12 -> 1 | D12: =B12*C12 -> 62 | E12: ='Prodotti Finiti'!$C$12 -> 0.13333333 | F12: =B12*E12 -> 8.2666667 | G12: =D12-F12 -> 53.733333 | H12: =IF($G$28=0,"",G12/$G$28) -> 0.013345157
A13: COCA COLA 0,2L | B13: ='Vendite 2025'!$F$8 -> 71 | C13: ='Prodotti Finiti'!$B$13 -> 2.5 | D13: =B13*C13 -> 177.5 | E13: ='Prodotti Finiti'!$C$13 -> 0.78135155 | F13: =B13*E13 -> 55.47596 | G13: =D13-F13 -> 122.02404 | H13: =IF($G$28=0,"",G13/$G$28) -> 0.030305769
A14: COCA COLA 0,4L | B14: ='Vendite 2025'!$F$9 -> 90 | C14: ='Prodotti Finiti'!$B$14 -> 4 | D14: =B14*C14 -> 360 | E14: ='Prodotti Finiti'!$C$14 -> 1.5004831 | F14: =B14*E14 -> 135.04348 | G14: =D14-F14 -> 224.95652 | H14: =IF($G$28=0,"",G14/$G$28) -> 0.055869978
A15: SPRITE 0,33L | B15: 0 | C15: ='Prodotti Finiti'!$B$15 -> 2 | D15: =B15*C15 -> 0 | E15: ='Prodotti Finiti'!$C$15 -> 0.79259333 | F15: =B15*E15 -> 0 | G15: =D15-F15 -> 0 | H15: =IF($G$28=0,"",G15/$G$28) -> 0
A16: COCA COLA SENZA CAFFEINA 0,33L | B16: 0 | C16: ='Prodotti Finiti'!$B$16 -> 2 | D16: =B16*C16 -> 0 | E16: ='Prodotti Finiti'!$C$16 -> 0.79259333 | F16: =B16*E16 -> 0 | G16: =D16-F16 -> 0 | H16: =IF($G$28=0,"",G16/$G$28) -> 0
A17: THE LIMONE | B17: ='Vendite 2025'!$F$20 -> 29 | C17: ='Prodotti Finiti'!$B$17 -> 2 | D17: =B17*C17 -> 58 | E17: ='Prodotti Finiti'!$C$17 -> 0.79259333 | F17: =B17*E17 -> 22.985207 | G17: =D17-F17 -> 35.014793 | H17: =IF($G$28=0,"",G17/$G$28) -> 0.0086962392
A18: THE PESCA | B18: ='Vendite 2025'!$F$21 -> 48 | C18: ='Prodotti Finiti'!$B$18 -> 2 | D18: =B18*C18 -> 96 | E18: ='Prodotti Finiti'!$C$18 -> 0.79259333 | F18: =B18*E18 -> 38.04448 | G18: =D18-F18 -> 57.95552 | H18: =IF($G$28=0,"",G18/$G$28) -> 0.014393775
A19: BIRRA ROSSA 0,2L | B19: ='Vendite 2025'!$F$6 -> 15 | C19: ='Prodotti Finiti'!$B$19 -> 3 | D19: =B19*C19 -> 45 | E19: ='Prodotti Finiti'!$C$19 -> 1.0468092 | F19: =B19*E19 -> 15.702138 | G19: =D19-F19 -> 29.297862 | H19: =IF($G$28=0,"",G19/$G$28) -> 0.0072763878
A20: BIRRA ROSSA 0,4L | B20: ='Vendite 2025'!$F$7 -> 53 | C20: ='Prodotti Finiti'!$B$20 -> 5 | D20: =B20*C20 -> 265 | E20: ='Prodotti Finiti'!$C$20 -> 2.0313984 | F20: =B20*E20 -> 107.66411 | G20: =D20-F20 -> 157.33589 | H20: =IF($G$28=0,"",G20/$G$28) -> 0.039075784
A21: BIRRA BIONDA 0,2L | B21: ='Vendite 2025'!$F$4 -> 66 | C21: ='Prodotti Finiti'!$B$21 -> 2.5 | D21: =B21*C21 -> 165 | E21: ='Prodotti Finiti'!$C$21 -> 0.90810955 | F21: =B21*E21 -> 59.93523 | G21: =D21-F21 -> 105.06477 | H21: =IF($G$28=0,"",G21/$G$28) -> 0.026093782
A22: BIRRA BIONDA 0,4L | B22: ='Vendite 2025'!$F$5 -> 171 | C22: ='Prodotti Finiti'!$B$22 -> 4 | D22: =B22*C22 -> 684 | E22: ='Prodotti Finiti'!$C$22 -> 1.7539991 | F22: =B22*E22 -> 299.93385 | G22: =D22-F22 -> 384.06615 | H22: =IF($G$28=0,"",G22/$G$28) -> 0.095386288
A23: VINO BIANCO 0,2L | B23: ='Vendite 2025'!$F$22 -> 34 | C23: ='Prodotti Finiti'!$B$23 -> 2.5 | D23: =B23*C23 -> 85 | E23: ='Prodotti Finiti'!$C$23 -> 0.83410435 | F23: =B23*E23 -> 28.359548 | G23: =D23-F23 -> 56.640452 | H23: =IF($G$28=0,"",G23/$G$28) -> 0.014067166
A24: SPRITZ APEROL | B24: ='Vendite 2025'!$F$18 -> 22 | C24: ='Prodotti Finiti'!$B$24 -> 3.5 | D24: =B24*C24 -> 77 | E24: ='Prodotti Finiti'!$C$24 -> 1.4013825 | F24: =B24*E24 -> 30.830416 | G24: =D24-F24 -> 46.169584 | H24: =IF($G$28=0,"",G24/$G$28) -> 0.011466632
A25: SPRITZ CAMPARI | B25: ='Vendite 2025'!$F$19 -> 11 | C25: ='Prodotti Finiti'!$B$25 -> 3.5 | D25: =B25*C25 -> 38.5 | E25: ='Prodotti Finiti'!$C$25 -> 1.6219992 | F25: =B25*E25 -> 17.841991 | G25: =D25-F25 -> 20.658009 | H25: =IF($G$28=0,"",G25/$G$28) -> 0.0051306025
A26: ANELLI DI CIPOLLA | B26: 0 | C26: ='Prodotti Finiti'!$B$26 -> 3.5 | D26: =B26*C26 -> 0 | E26: ='Prodotti Finiti'!$C$26 -> 1.1818036 | F26: =B26*E26 -> 0 | G26: =D26-F26 -> 0 | H26: =IF($G$28=0,"",G26/$G$28) -> 0
A27: OLIVE ALL'ASCOLANA | B27: 0 | C27: ='Prodotti Finiti'!$B$27 -> 3.5 | D27: =B27*C27 -> 0 | E27: ='Prodotti Finiti'!$C$27 -> 1.2602861 | F27: =B27*E27 -> 0 | G27: =D27-F27 -> 0 | H27: =IF($G$28=0,"",G27/$G$28) -> 0
A28: TOTALE | B28: =SUM(B2:B27) -> 1749 | D28: =SUM(D2:D27) -> 6152.5 | F28: =SUM(F2:F27) -> 2126.0706 | G28: =SUM(G2:G27) -> 4026.4294
A30: Margine % complessivo | B30: =G28/D28 -> 0.65443794
A31: Volumi 2025 valorizzati con prezzi e costi attuali. I prodotti nuovi (combo hamburger, anelli, olive, Sprite) non erano in vendita nel 2025: inserire una stima di pezzi nelle celle gialle. Non include costi fissi.

Sheet Fabbisogno 2026
A1: GIORNATE 2026: 7 TOTALI - Weekend 1 gio-dom (4 gg), Weekend 2 ven-dom (3 gg)
A2: Weekend 1 (gio-dom) - fattore vs stesse giornate 2025 | B2: 1
A3: Weekend 2 (ven-dom) - fattore vs stesse giornate 2025 | B3: 1
A4: Weekend 1 = tutte e 4 le giornate 2025. Weekend 2 = solo ven+sab+dom 2025. Prodotti nuovi (combo hamburger, anelli, olive, Sprite): nessuno storico, inserire i pezzi previsti nelle celle gialle.
A5: PEZZI PREVISTI PER PRODOTTO
A6: Prodotto | B6: Weekend 1 | C6: Weekend 2 | D6: Totale 2026
A7: PIADINA P.CRUDO | B7: =ROUND(SUM('Vendite 2025'!$B$13:$E$13)*$B$2,0) -> 63 | C7: =ROUND(SUM('Vendite 2025'!$C$13:$E$13)*$B$3,0) -> 43 | D7: =B7+C7 -> 106
A8: PIADINA P.CRUDO E FORMAGGIO | B8: =ROUND(SUM('Vendite 2025'!$B$14:$E$14)*$B$2,0) -> 133 | C8: =ROUND(SUM('Vendite 2025'!$C$14:$E$14)*$B$3,0) -> 105 | D8: =B8+C8 -> 238
A9: PIADINA P.COTTO | B9: =ROUND(SUM('Vendite 2025'!$B$11:$E$11)*$B$2,0) -> 66 | C9: =ROUND(SUM('Vendite 2025'!$C$11:$E$11)*$B$3,0) -> 56 | D9: =B9+C9 -> 122
A10: PIADINA P.COTTO E FORMAGGIO | B10: =ROUND(SUM('Vendite 2025'!$B$12:$E$12)*$B$2,0) -> 128 | C10: =ROUND(SUM('Vendite 2025'!$C$12:$E$12)*$B$3,0) -> 100 | D10: =B10+C10 -> 228
A11: PIADINA SALAME | B11: =ROUND(SUM('Vendite 2025'!$B$15:$E$15)*$B$2,0) -> 35 | C11: =ROUND(SUM('Vendite 2025'!$C$15:$E$15)*$B$3,0) -> 32 | D11: =B11+C11 -> 67
A12: PIADINA SALAME E FORMAGGIO | B12: =ROUND(SUM('Vendite 2025'!$B$16:$E$16)*$B$2,0) -> 90 | C12: =ROUND(SUM('Vendite 2025'!$C$16:$E$16)*$B$3,0) -> 73 | D12: =B12+C12 -> 163
A13: PIADINA SOLO FORMAGGIO | B13: =ROUND(SUM('Vendite 2025'!$B$17:$E$17)*$B$2,0) -> 15 | C13: =ROUND(SUM('Vendite 2025'!$C$17:$E$17)*$B$3,0) -> 13 | D13: =B13+C13 -> 28
A14: HAMBURGER CON PATATINE | B14: 0 | C14: 0 | D14: =B14+C14 -> 0
A15: PATATINE FRITTE | B15: =ROUND(SUM('Vendite 2025'!$B$10:$E$10)*$B$2,0) -> 341 | C15: =ROUND(SUM('Vendite 2025'!$C$10:$E$10)*$B$3,0) -> 289 | D15: =B15+C15 -> 630
A16: ACQUA NATURALE 0,5L | B16: =ROUND(SUM('Vendite 2025'!$B$3:$E$3)*$B$2,0) -> 206 | C16: =ROUND(SUM('Vendite 2025'!$C$3:$E$3)*$B$3,0) -> 175 | D16: =B16+C16 -> 381
A17: ACQUA FRIZZANTE 0,5L | B17: =ROUND(SUM('Vendite 2025'!$B$2:$E$2)*$B$2,0) -> 62 | C17: =ROUND(SUM('Vendite 2025'!$C$2:$E$2)*$B$3,0) -> 51 | D17: =B17+C17 -> 113
A18: COCA COLA 0,2L | B18: =ROUND(SUM('Vendite 2025'!$B$8:$E$8)*$B$2,0) -> 71 | C18: =ROUND(SUM('Vendite 2025'!$C$8:$E$8)*$B$3,0) -> 62 | D18: =B18+C18 -> 133
A19: COCA COLA 0,4L | B19: =ROUND(SUM('Vendite 2025'!$B$9:$E$9)*$B$2,0) -> 90 | C19: =ROUND(SUM('Vendite 2025'!$C$9:$E$9)*$B$3,0) -> 76 | D19: =B19+C19 -> 166
A20: SPRITE 0,33L | B20: 0 | C20: 0 | D20: =B20+C20 -> 0
A21: COCA COLA SENZA CAFFEINA 0,33L | B21: 0 | C21: 0 | D21: =B21+C21 -> 0
A22: THE LIMONE | B22: =ROUND(SUM('Vendite 2025'!$B$20:$E$20)*$B$2,0) -> 29 | C22: =ROUND(SUM('Vendite 2025'!$C$20:$E$20)*$B$3,0) -> 24 | D22: =B22+C22 -> 53
A23: THE PESCA | B23: =ROUND(SUM('Vendite 2025'!$B$21:$E$21)*$B$2,0) -> 48 | C23: =ROUND(SUM('Vendite 2025'!$C$21:$E$21)*$B$3,0) -> 41 | D23: =B23+C23 -> 89
A24: BIRRA ROSSA 0,2L | B24: =ROUND(SUM('Vendite 2025'!$B$6:$E$6)*$B$2,0) -> 15 | C24: =ROUND(SUM('Vendite 2025'!$C$6:$E$6)*$B$3,0) -> 14 | D24: =B24+C24 -> 29
A25: BIRRA ROSSA 0,4L | B25: =ROUND(SUM('Vendite 2025'!$B$7:$E$7)*$B$2,0) -> 53 | C25: =ROUND(SUM('Vendite 2025'!$C$7:$E$7)*$B$3,0) -> 47 | D25: =B25+C25 -> 100
A26: BIRRA BIONDA 0,2L | B26: =ROUND(SUM('Vendite 2025'!$B$4:$E$4)*$B$2,0) -> 66 | C26: =ROUND(SUM('Vendite 2025'!$C$4:$E$4)*$B$3,0) -> 53 | D26: =B26+C26 -> 119
A27: BIRRA BIONDA 0,4L | B27: =ROUND(SUM('Vendite 2025'!$B$5:$E$5)*$B$2,0) -> 171 | C27: =ROUND(SUM('Vendite 2025'!$C$5:$E$5)*$B$3,0) -> 146 | D27: =B27+C27 -> 317
A28: VINO BIANCO 0,2L | B28: =ROUND(SUM('Vendite 2025'!$B$22:$E$22)*$B$2,0) -> 34 | C28: =ROUND(SUM('Vendite 2025'!$C$22:$E$22)*$B$3,0) -> 23 | D28: =B28+C28 -> 57
A29: SPRITZ APEROL | B29: =ROUND(SUM('Vendite 2025'!$B$18:$E$18)*$B$2,0) -> 22 | C29: =ROUND(SUM('Vendite 2025'!$C$18:$E$18)*$B$3,0) -> 16 | D29: =B29+C29 -> 38
A30: SPRITZ CAMPARI | B30: =ROUND(SUM('Vendite 2025'!$B$19:$E$19)*$B$2,0) -> 11 | C30: =ROUND(SUM('Vendite 2025'!$C$19:$E$19)*$B$3,0) -> 9 | D30: =B30+C30 -> 20
A31: ANELLI DI CIPOLLA | B31: 0 | C31: 0 | D31: =B31+C31 -> 0
A32: OLIVE ALL'ASCOLANA | B32: 0 | C32: 0 | D32: =B32+C32 -> 0
A33: TOTALE PEZZI | B33: =SUM(B7:B32) -> 1749 | C33: =SUM(C7:C32) -> 1448 | D33: =SUM(D7:D32) -> 3197
A35: FABBISOGNO MATERIE PRIME
A36: Materia Prima | B36: Weekend 1 | C36: Weekend 2 | D36: Totale 2026 | E36: Unita' | F36: Colli / Confezioni da ordinare (totale)
A37: Piadine (pezzi) | B37: =B7+B8+B9+B10+B11+B12+B13 -> 530 | C37: =C7+C8+C9+C10+C11+C12+C13 -> 422 | D37: =B37+C37 -> 952 | E37: pezzi | F37: =CEILING(D37/24,1)&" cartoni da 24" -> 40 cartoni da 24
A38: Pagnottine hamburger (pezzi) | B38: =B14 -> 0 | C38: =C14 -> 0 | D38: =B38+C38 -> 0 | E38: pezzi | F38: =CEILING(D38/(Parametri!$B$45*Parametri!$B$46),1)&" cartoni" -> 0 cartoni
A39: Carne hamburger (pezzi) | B39: =B14 -> 0 | C39: =C14 -> 0 | D39: =B39+C39 -> 0 | E39: pezzi
A40: Prosciutto Crudo (kg) | B40: =(B7*Parametri!$B$4+B8*Parametri!$B$5)/1000 -> 16.94 | C40: =(C7*Parametri!$B$4+C8*Parametri!$B$5)/1000 -> 12.7 | D40: =B40+C40 -> 29.64 | E40: kg
A41: Prosciutto Cotto (kg) | B41: =(B9*Parametri!$B$4+B10*Parametri!$B$5)/1000 -> 16.84 | C41: =(C9*Parametri!$B$4+C10*Parametri!$B$5)/1000 -> 13.6 | D41: =B41+C41 -> 30.44 | E41: kg
...

Sheet Menu HTML
A1: CODICE HTML DEL MENU - nomi, descrizioni e prezzi si aggiornano da 'Prodotti Finiti'
A3: I prezzi qui sotto sono FORMULE collegate al foglio 'Prodotti Finiti' (colonna B).
A4: Cambiando un prezzo li', il codice HTML si aggiorna da solo: le righe VERDI sono i prezzi collegati.
A5: Le righe AZZURRE sono i nomi e le descrizioni dei prodotti (colonne V e W di 'Prodotti Finiti').
A6: Le righe ARANCIONI sono i testi fissi (titolo, sottotitolo, sezioni, piede) e vengono dal foglio 'Testi Menu'.
A7: Quindi tutto il menu (nomi, descrizioni e prezzi) si aggiorna modificando solo 'Prodotti Finiti'.
A9: Come rigenerare il file index.html:
A10: 1. Clicca sull'intestazione della colonna A per selezionarla tutta.
A11: 2. Copia (Ctrl+C), apri il Blocco note e incolla (Ctrl+V).
A12: 3. Cancella queste righe di istruzioni in cima, lasciando solo da <!DOCTYPE html> in poi.
A13: 4. Salva come 'index.html', tipo 'Tutti i file', codifica 'UTF-8'.
A15: Come pubblicarlo su GitHub Pages:
... A30: <meta name="viewport" content="width=device-width, initial-scale=1">
A31: ="<title>"&'Testi Menu'!$B$4&"</title>" -> <title>Menu · Festa di Sant'Agostino 2026</title>
A32: <meta name="description" content="Il menu della Festa di Sant'Agostino 2026: piadine, hamburger, fritti e bevande.">
A33: <link rel="preconnect" href="https://fonts.googleapis.com">
A34: <link rel="preconnect" href="https://fonts.gstatic.com" crossorigin>
A35: <link href="https://fonts.googleapis.com/css2?family=Archivo+Black&family=Archivo:ital,wght@0,400;0,500;0,600;1,400&display=swap" rel="stylesheet">
A36: <style>
A37: :root{
A38: --verde:#14452F;
A39: --verde-scuro:#0E3222;
A40: --panna:#FBF6EA;
A41: --rosso:#B5232B;
A42: --mais:#E8B33C;
A43: --inchiostro:#1A211D;
... A315: <div class="wrap">
A316: =" <p class=""occhiello"">"&'Testi Menu'!$B$5&"</p>" -> <p class="occhiello">Parrocchia di Sant'Agostino · Ferrara</p>
A317: =" <h1 class=""titolo""><span class=""riga1"">"&'Testi Menu'!$B$6&"</span><span class=""riga2"">"&'Testi Menu'!$B$7&"</span><span class=""anno"">"&'Testi Menu'!$B$8&"</span></h1>" -> <h1 class="titolo"><span class="riga1">Festa di</span><span class="riga2">Sant'Agostino</span><span class="anno">2026</span></h1>
A318: =" <p class=""sottotitolo"">"&'Testi Menu'!$B$9&IF('Testi Menu'!$B$10="","","<br>"&'Testi Menu'!$B$10)&IF('Testi Menu'!$B$11="","","<br>"&'Testi Menu'!$B$11)&"</p>" -> <p class="sottotitolo">Due weekend di piadine e hamburger!!<br>Si ordina alla cassa e si ritirano le bevande.<br>Il cibo verrà servito al tavolo.</p>
A319: </div>
A320: </header>
A322: <nav class="banchi" aria-label="Sezioni del menu">
A323: <ul>
A324: =" <li><a href=""#cucina"">"&'Testi Menu'!$B$13&"</a></li>" -> <li><a href="#cucina">Cucina</a></li>
A325: =" <li><a href=""#fritti"">"&'Testi Menu'!$B$15&"</a></li>" -> <li><a href="#fritti">Fritti</a></li>
A326: =" <li><a href=""#bevande"">"&'Testi Menu'!$B$17&"</a></li>" -> <li><a href="#bevande">Bevande</a></li>
A327: </ul>
A328: </nav>
A330: <main class="wrap">
...

Sheet Testi Menu
A1: TESTI DEL MENU - modifica le celle gialle, il foglio 'Menu HTML' si aggiorna da solo
A2: Elemento | B2: Testo (modificabile) | C2: Note
A3: TESTATA
A4: Titolo della finestra del browser | B4: Menu · Festa di Sant'Agostino 2026 | C4: Compare nella scheda del browser e nei preferiti.
A5: Occhiello (riga sopra il titolo) | B5: Parrocchia di Sant'Agostino · Ferrara
A6: Titolo - prima riga | B6: Festa di
A7: Titolo - seconda riga | B7: Sant'Agostino | C7: La riga grande.
A8: Titolo - terza riga (anno o date) | B8: 2026 | C8: Qui puoi mettere le date esatte, es. 27-30 agosto e 4-6 settembre.
A9: Sottotitolo - prima riga | B9: Due weekend di piadine e hamburger!!
A10: Sottotitolo - seconda riga | B10: Si ordina alla cassa e si ritirano le bevande. | C10: Lascia vuota per saltare la riga.
A11: Sottotitolo - terza riga | B11: Il cibo verrà servito al tavolo. | C11: Lascia vuota per saltare la riga.
A12: SEZIONI DEL MENU
A13: Sezione 1 - nome | B13: Cucina | C13: Compare sull'insegna e nel menu di navigazione.
A14: Sezione 1 - descrizione | B14: Piadine e hamburger
A15: Sezione 2 - nome | B15: Fritti
A16: Sezione 2 - descrizione | B16: Dalla friggitrice
A17: Sezione 3 - nome | B17: Bevande
A18: Sezione 3 - descrizione | B18: Spina e bottiglia
A19: PIEDE PAGINA
A20: Piede - prima riga | B20: Prezzi in euro. Bicchieri e stoviglie compostabili. | C20: La parte dopo il primo punto viene messa in grassetto.
A21: Piede - seconda riga | B21: Grazie per fare la differenziata negli appositi contenitori.
A23: Dopo aver modificato questi testi, vai nel foglio 'Menu HTML', copia la colonna A e salvala come index.html.

Sheet Note
A1: Note sui dati
A3: Fonte: schermate ordini fornitore (screenshot gestionale) per PARROCCHIA S. AGOSTINO VESCOVO DOTT.
A4: Ordine 05128912 - Inviato 12/08/2026 - Consegna 26/08/2026 (con PZ.500 ciotole compostabili)
A5: Ordine 04342413 - Aggiunta - Inviato 13/08/2026 - Consegna 14/08/2026
A7: 'Pezzi per Collo' = quantita' di pezzi/unita' contenute in ogni CT (cartone), CF (confezione) o PZ (pezzo singolo, valore 1).
A8: 'Prezzo Unitario Collo' = Prezzo Totale Netto / Qta Ordinata (prezzo di un singolo collo/cartone/confezione).
A9: 'Costo per Pezzo' = Prezzo Unitario Collo / Pezzi per Collo (costo della singola unita' venduta, usato come base per il costo dei prodotti finiti).
A11: Verificare 'Pezzi per Collo' per gli articoli PZ (es. ketchup mono, maionese mono, prosciutto): il valore 1 assume che il prezzo si riferisca gia' alla singola confezione/pezzo mostrato in foto; da confermare con il fornitore se necessario.

Sheet Materie Prime
A1: Codice | B1: Articolo | C1: UM | D1: Pezzi per Collo | E1: Qta Ordinata (Collo) | F1: Prezzo Totale Netto (€) | G1: Prezzo Unitario Collo (€) | H1: Costo per Pezzo (€) | I1: Ordine | J1: Colonna 'Prezzo Totale Netto' rappresenta: | K1: Prezzo unitario per collo | L1: Categoria IVA | M1: Aliquota IVA | N1: Prezzo Totale con IVA (€)
A2: 56833 | B2: SOFT SOFT TOVAGLIOLI 38X38 BIANCHI X35 (COD.EAN 8057438681150) | C2: CT | D2: 48 | E2: 1 | F2: 46.56 | G2: =IF($K$1="Totale riga",N2/E2,N2) -> 56.8032 | H2: =G2/D2 -> 1.1834 | I2: 05128912 | J2: 14/08/2026 | L2: Altro | M2: =IF(L2="Pane/Piadina",0.04,IF(OR(L2="Salumi",L2="Formaggio"),0.1,0.22)) -> 0.22 | N2: =F2*(1+M2) -> 56.8032
A3: 92869 | B3: OLITALIA OLIO GIRASOLE ALTOLEICO LT.10 | C3: CT | D3: 2 | E3: 3 | F3: 47.1 | G3: =IF($K$1="Totale riga",N3/E3,N3) -> 57.462 | H3: =G3/D3 -> 28.731 | I3: 05128912 | J3: 14/08/2026 | L3: Altro | M3: =IF(L3="Pane/Piadina",0.04,IF(OR(L3="Salumi",L3="Formaggio"),0.1,0.22)) -> 0.22 | N3: =F3*(1+M3) -> 57.462
A4: 34654 | B4: BOTTARI SPIEDINI IN BAMBOO 25CM X 50 (COD.EAN 8016038983828) | C4: CF | D4: 12 | E4: 1 | F4: 9.84 | G4: =IF($K$1="Totale riga",N4/E4,N4) -> 12.0048 | H4: =G4/D4 -> 1.0004 | I4: 05128912 | J4: 14/08/2026 | L4: Altro | M4: =IF(L4="Pane/Piadina",0.04,IF(OR(L4="Salumi",L4="Formaggio"),0.1,0.22)) -> 0.22 | N4: =F4*(1+M4) -> 12.0048
A5: 93150 | B5: PIATTI PIANI PZ 50 PRESTO PRESTO (COD.EAN 8032532739044) | C5: CT | D5: 20 | E5: 1 | F5: 48.2 | G5: =IF($K$1="Totale riga",N5/E5,N5) -> 58.804 | H5: =G5/D5 -> 2.9402 | I5: 05128912 | J5: 14/08/2026 | L5: Altro | M5: =IF(L5="Pane/Piadina",0.04,IF(OR(L5="Salumi",L5="Formaggio"),0.1,0.22)) -> 0.22 | N5: =F5*(1+M5) -> 58.804
A6: 95822 | B6: ASTOR TOVAGLIETTE BIANCHE 30X40 X 200 PZ (EAN 8000875002521) | C6: PZ | D6: 1 | E6: 5 | F6: 3.25 | G6: =IF($K$1="Totale riga",N6/E6,N6) -> 3.965 | H6: =G6/D6 -> 3.965 | I6: 05128912 | J6: 14/08/2026 | L6: Altro | M6: =IF(L6="Pane/Piadina",0.04,IF(OR(L6="Salumi",L6="Formaggio"),0.1,0.22)) -> 0.22 | N6: =F6*(1+M6) -> 3.965
A7: 95365 | B7: BIFFI KETCHUP MONO GR.10 X 132 BS. | C7: PZ | D7: 1 | E7: 3 | F7: 10.05 | G7: =IF($K$1="Totale riga",N7/E7,N7) -> 12.261 | H7: =G7/D7 -> 12.261 | I7: 05128912 | J7: 14/08/2026 | L7: Altro | M7: =IF(L7="Pane/Piadina",0.04,IF(OR(L7="Salumi",L7="Formaggio"),0.1,0.22)) -> 0.22 | N7: =F7*(1+M7) -> 12.261
A8: 95408 | B8: BIFFI MAIONESE MONO GR.10 X 132 PZ. | C8: PZ | D8: 1 | E8: 3 | F8: 10.15 | G8: =IF($K$1="Totale riga",N8/E8,N8) -> 12.383 | H8: =G8/D8 -> 12.383 | I8: 05128912 | J8: 14/08/2026 | L8: Altro | M8: =IF(L8="Pane/Piadina",0.04,IF(OR(L8="Salumi",L8="Formaggio"),0.1,0.22)) -> 0.22 | N8: =F8*(1+M8) -> 12.383
A9: 84468 | B9: MEZZO PROSC. COTTO NEGRINI VAI PADUSE | C9: PZ | D9: 1 | E9: 6 | F9: 10.4 | G9: =IF($K$1="Totale riga",N9/E9,N9) -> 11.44 | H9: =G9/D9 -> 11.44 | I9: 05128912 | J9: 14/08/2026 | L9: Salumi | M9: =IF(L9="Pane/Piadina",0.04,IF(OR(L9="Salumi",L9="Formaggio"),0.1,0.22)) -> 0.1 | N9: =F9*(1+M9) -> 11.44
A10: 95551 | B10: PIADINA FRESCA ARTIGIANALE X 3 PZ. 300GR | C10: CT | D10: 8 | E10: 27 | F10: 15.12 | G10: =IF($K$1="Totale riga",N10/E10,N10) -> 15.7248 | H10: =G10/D10 -> 1.9656 | I10: 05128912 | J10: 14/08/2026 | L10: Pane/Piadina | M10: =IF(L10="Pane/Piadina",0.04,IF(OR(L10="Salumi",L10="Formaggio"),0.1,0.22)) -> 0.04 | N10: =F10*(1+M10) -> 15.7248
A11: 83106 | B11: ZARPELLON EDAMER FETTE 40% KG 1 (COD.FAN 8002226002587) | C11: PZ | D11: 1 | E11: 11 | F11: 6.58 | G11: =IF($K$1="Totale riga",N11/E11,N11) -> 7.238 | H11: =G11/D11 -> 7.238 | I11: 05128912 | J11: 14/08/2026 | L11: Formaggio | M11: =IF(L11="Pane/Piadina",0.04,IF(OR(L11="Salumi",L11="Formaggio"),0.1,0.22)) -> 0.1 | N11: =F11*(1+M11) -> 7.238
A12: 84501 | B12: NEGRINI SALAME FERRARESE GRAN ZIA | C12: CT | D12: 1 | E12: 3 | F12: 12.9 | G12: =IF($K$1="Totale riga",N12/E12,N12) -> 14.19 | H12: =G12/D12 -> 14.19 | I12: 05128912 | J12: 14/08/2026 | L12: Salumi | M12: =IF(L12="Pane/Piadina",0.04,IF(OR(L12="Salumi",L12="Formaggio"),0.1,0.22)) -> 0.1 | N12: =F12*(1+M12) -> 14.19
A13: 84480 | B13: BRUGNOLO CRUDO NAZIONALE RISERVA ADDOBBO (COD.EAN 2003742016603) | C13: CT | D13: 1 | E13: 3 | F13: 12.85 | G13: =IF($K$1="Totale riga",N13/E13,N13) -> 14.135 | H13: =G13/D13 -> 14.135 | I13: 05128912 | J13: 14/08/2026 | L13: Salumi | M13: =IF(L13="Pane/Piadina",0.04,IF(OR(L13="Salumi",L13="Formaggio"),0.1,0.22)) -> 0.1 | N13: =F13*(1+M13) -> 14.135
A14: 40982 | B14: GARDAPAN PAGNOTTINE SESAMO GR.300 (COD.EAN 8000744000344) | C14: CT | D14: 7 | E14: 7 | F14: 8.47 | G14: =IF($K$1="Totale riga",N14/E14,N14) -> 8.8088 | H14: =G14/D14 -> 1.2584 | I14: 04342413 | J14: 14/08/2026 | L14: Pane/Piadina | M14: =IF(L14="Pane/Piadina",0.04,IF(OR(L14="Salumi",L14="Formaggio"),0.1,0.22)) -> 0.04 | N14: =F14*(1+M14) -> 8.8088
E16: Totale Imponibile: | F16: =SUM(F2:F14) -> 241.47

Sheet Materie Prime Bevande
A1: Prodotto | B1: Fornitore | C1: Formato | D1: Unita' elementare | E1: Quantita' per collo (in unita' elementari) | F1: Prezzo Collo IVA Esclusa (€) | G1: Aliquota IVA | H1: Prezzo Collo con IVA (€) | I1: Prezzo per unita' elementare (€)
A2: Birra Falkenturm Export Hell | B2: Barozzi Bevande | C2: Fusto LT.20 VOL 5,1% | D2: 1 litro | E2: 20 | F2: 57.69 | G2: 0.22 | H2: =F2*(1+G2) -> 70.3818 | I2: =H2/E2 -> 3.51909
A3: Birra Vikingen Alt Dunkel Rossa | B3: Barozzi Bevande | C3: Fusto LT.15.3 VOL 5,1% | D3: 1 litro | E3: 15.3 | F3: 52.83 | G3: 0.22 | H3: =F3*(1+G3) -> 64.4526 | I3: =H3/E3 -> 4.2125882
A4: Vino Glera Bianco IGT Maccari Ca' Vigna | B4: Barozzi Bevande | C4: Fusto LT.25 | D4: 1 litro | E4: 25 | F4: 64.53 | G4: 0.22 | H4: =F4*(1+G4) -> 78.7266 | I4: =H4/E4 -> 3.149064
A5: Coca Cola Premix | B5: Barozzi Bevande | C5: Fusto LT.18 | D5: 1 litro | E5: 18 | F5: 42.57 | G5: 0.22 | H5: =F5*(1+G5) -> 51.9354 | I5: =H5/E5 -> 2.8853
A6: Bicchiere Compostabile ISAP P300cc (tacca 0.2L) | B6: Barozzi Bevande | C6: Fila x50 | D6: 1 bicchiere | E6: 50 | F6: 3.95 | G6: 0.22 | H6: =F6*(1+G6) -> 4.819 | I6: =H6/E6 -> 0.09638
A7: Bicchiere Compostabile ISAP P500cc (tacca 0.40L) | B7: Barozzi Bevande | C7: Fila x50 | D7: 1 bicchiere | E7: 50 | F7: 5.35 | G7: 0.22 | H7: =F7*(1+G7) -> 6.527 | I7: =H7/E7 -> 0.13054
A8: The Lipton Limone | B8: Barozzi Bevande | C8: Cartone 24 latt. 0.33L | D8: 1 lattina (0,33L) | E8: 24 | F8: 13.36 | G8: 0.22 | H8: =F8*(1+G8) -> 16.2992 | I8: =H8/E8 -> 0.67913333
A9: The Lipton Pesca | B9: Barozzi Bevande | C9: Cartone 24 latt. 0.33L | D9: 1 lattina (0,33L) | E9: 24 | F9: 13.36 | G9: 0.22 | H9: =F9*(1+G9) -> 16.2992 | I9: =H9/E9 -> 0.67913333
A10: Bicchiere Compostabile ISAP P400cc (tacca 0.3L) | B10: Barozzi Bevande | C10: Fila x50 | D10: 1 bicchiere | E10: 50 | F10: 4.65 | G10: 0.22 | H10: =F10*(1+G10) -> 5.673 | I10: =H10/E10 -> 0.11346
A11: Aperol 11% | B11: Barozzi Bevande | C11: Bottiglia LT.1 | D11: 1 litro | E11: 1 | F11: 11 | G11: 0.22 | H11: =F11*(1+G11) -> 13.42 | I11: =H11/E11 -> 13.42
A12: Bitter Campari 25% | B12: Barozzi Bevande | C12: Bottiglia LT.1 | D12: 1 litro | E12: 1 | F12: 14.1 | G12: 0.22 | H12: =F12*(1+G12) -> 17.202 | I12: =H12/E12 -> 17.202
A13: Sprite Lattina 0,33L | B13: Barozzi Bevande | C13: Cartone 24 latt. 0.33L | D13: 1 lattina (0,33L) | E13: 24 | F13: 13.36 | G13: 0.22 | H13: =F13*(1+G13) -> 16.2992 | I13: =H13/E13 -> 0.67913333
A14: Coca Cola Senza Caffeina Lattina 0,33L | B14: Barozzi Bevande | C14: Cartone 24 latt. 0.33L | D14: 1 lattina (0,33L) | E14: 24 | F14: 13.36 | G14: 0.22 | H14: =F14*(1+G14) -> 16.2992 | I14: =H14/E14 -> 0.67913333

Sheet Materie Prime IperTosano
A1: Prodotto | B1: Marca | C1: Cod.Art | D1: Formato | E1: Unita' elementare | F1: Qta per collo | G1: Prezzo Collo IVA INCLUSA (€) | H1: Prezzo per unita' elementare (€)
A2: Acqua Naturale Beber 0,5L | B2: BEBER | C2: 0275944 | D2: ML.500 x 12 PZ | E2: 1 bottiglia (0,5L) | F2: 12 | G2: 1.6 | H2: =G2/F2 -> 0.13333333
A3: Acqua Frizzante Beber 0,5L | B3: BEBER | C3: 0275947 | D3: ML.500 x 12 PZ | E3: 1 bottiglia (0,5L) | F3: 12 | G3: 1.6 | H3: =G3/F3 -> 0.13333333
A4: Patatine Fritte Surgelate Ecofrost | B4: ECOFROST | C4: 0151329 | D4: KG. 2,5 | E4: 1 kg | F4: 2.5 | G4: 3.9 | H4: =G4/F4 -> 1.56
A5: Ghiaccio a Cubetti Easy Ice | B5: EASY ICE | C5: 0207504 | D5: KG. 2 | E5: 1 kg | F5: 2 | G5: 1.3 | H5: =G5/F5 -> 0.65
A6: Anelli di Cipolla Pastellati | B6: L'ASCOLANA | C6: 0201103 | D6: GR. 400 | E6: 1 kg | F6: 0.4 | G6: 2.75 | H6: =G6/F6 -> 6.875
A7: Olive all'Ascolana | B7: REGEL | C7: 0168576 | D7: GR. 500 | E7: 1 kg | F7: 0.5 | G7: 3.29 | H7: =G7/F7 -> 6.58

Sheet Prezzi Unitari
A1: Materia Prima | B1: Unita' elementare | C1: Quantita' per collo (in unita' elementari) | D1: Prezzo Unitario Collo (€) [da Materie Prime] | E1: Prezzo per unita' elementare (€) | F1: Note
A2: Olio Girasole Altoleico (LT.10 x2 per CT) | B2: 1 litro | C2: 20 | D2: ='Materie Prime'!G3 -> 57.462 | E2: =IF(C2="","",D2/C2) -> 2.8731 | F2: 20 litri per CT (2 taniche da 10L)
A3: Biffi Ketchup mono 10g x132 | B3: 1 bustina (10g) | C3: 132 | D3: ='Materie Prime'!G7 -> 12.261 | E3: =IF(C3="","",D3/C3) -> 0.092886364 | F3: 132 bustine per confezione
A4: Biffi Maionese mono 10g x132 | B4: 1 bustina (10g) | C4: 132 | D4: ='Materie Prime'!G8 -> 12.383 | E4: =IF(C4="","",D4/C4) -> 0.093810606 | F4: 132 bustine per confezione
A5: Mezzo Prosciutto Cotto Negrini | B5: 100 g | C5: 10 | D5: ='Materie Prime'!N9 -> 11.44 | E5: =IF(C5="","",D5/C5) -> 1.144 | F5: Prezzo con IVA (10% salumi), gia' al kg; 10 unita' da 100g per kg
A6: Piadina Fresca Artigianale (x3, 300g) | B6: 1 piadina | C6: 24 | D6: ='Materie Prime'!G10 -> 15.7248 | E6: =IF(C6="","",D6/C6) -> 0.6552 | F6: Confermato: 8 confezioni x 3 piadine = 24 piadine per cartone (27 cartoni ordinati)
A7: Zarpellon Edamer fette 40% (KG1) | B7: 100 g | C7: 10 | D7: ='Materie Prime'!G11 -> 7.238 | E7: =IF(C7="","",D7/C7) -> 0.7238 | F7: Prezzo con IVA 10% (formaggio)
A8: Negrini Salame Ferrarese Gran Zia | B8: 100 g | C8: 10 | D8: ='Materie Prime'!N12 -> 14.19 | E8: =IF(C8="","",D8/C8) -> 1.419 | F8: Prezzo con IVA (10% salumi), gia' al kg; 10 unita' da 100g per kg
A9: Brugnolo Crudo Naz. Riserva Addobbo | B9: 100 g | C9: 10 | D9: ='Materie Prime'!N13 -> 14.135 | E9: =IF(C9="","",D9/C9) -> 1.4135 | F9: Prezzo con IVA (10% salumi), gia' al kg; 10 unita' da 100g per kg
A10: Gardapan Pagnottine Sesamo (GR.300) | B10: 1 pagnottina | C10: =Parametri!$B$45*Parametri!$B$46 -> 28 | D10: ='Materie Prime'!G14 -> 8.8088 | E10: =IF(C10="","",D10/C10) -> 0.3146 | F10: CONFERMATO: 7 sacchetti x 4 panini = 28 pagnottine per cartone (7 cartoni ordinati = 196 panini totali).
A11: Soft Soft Tovaglioli 38x38 (X35) | B11: 1 tovagliolo | C11: 1680 | D11: ='Materie Prime'!G2 -> 56.8032 | E11: =IF(C11="","",D11/C11) -> 0.033811429 | F11: Ipotesi: 48 pacchetti x 35 tovaglioli = 1680 per cartone. Da confermare.
A12: Piatti Piani PZ50 Presto Presto | B12: 1 piatto | C12: 1000 | D12: ='Materie Prime'!G5 -> 58.804 | E12: =IF(C12="","",D12/C12) -> 0.058804 | F12: Ipotesi: 20 pacchetti x 50 piatti = 1000 per cartone. Da confermare.
A13: Bottari Spiedini Bamboo 25cm (x50) | B13: 1 stecchino | C13: 600 | D13: ='Materie Prime'!G4 -> 12.0048 | E13: =IF(C13="","",D13/C13) -> 0.020008 | F13: Ipotesi: 12 confezioni x 50 stecchini = 600 per collo. Da confermare.

Sheet Parametri
A1: COMPOSIZIONE PIADINE
A2: Ripieno totale per piadina (g) | B2: 100
A3: Quota salume quando c'e' formaggio (%) | B3: 0.8
A4: Grammi salume senza formaggio | B4: =B2 -> 100
A5: Grammi salume con formaggio | B5: =B2*B3 -> 80
A6: Grammi formaggio con salume | B6: =B2*(1-B3) -> 20
A7: Grammi formaggio da solo | B7: =B2 -> 100
A8: COMPOSIZIONE PATATINE FRITTE
A9: Grammi patatine surgelate per porzione | B9: 200
A10: Olio assorbito (% del peso) | B10: 0.1
A11: Densita' olio (kg/L) | B11: 0.92
A12: Olio assorbito per porzione (ml) | B12: =B9*B10/B11 -> 21.73913
A13: N. piatti per porzione | B13: 1
A14: N. tovaglioli per porzione | B14: 1
A15: N. bustine ketchup per porzione | B15: 1
A16: N. bustine maionese per porzione | B16: 1
A17: N. stecchini per porzione | B17: 2
A18: COMPOSIZIONE SPRITZ
A19: Volume bicchiere servito (ml) | B19: 300
A20: N. cubetti ghiaccio | B20: 5
A21: Volume per cubetto (ml) | B21: 25
A22: Peso per cubetto (g) | B22: 23
A23: Volume ghiaccio (ml) | B23: =B20*B21 -> 125
A24: Volume liquido effettivo (ml) | B24: =B19-B23 -> 175
A25: Parti vino | B25: 4
A26: Parti liquore | B26: 2
A27: Vino per bicchiere (ml) | B27: =B24*B25/(B25+B26) -> 116.66667
A28: Liquore per bicchiere (ml) | B28: =B24*B26/(B25+B26) -> 58.333333
A29: Ghiaccio per bicchiere (g) | B29: =B20*B22 -> 115
A30: CO2 (SPINA)
A31: N. bombole 5kg usate 2025 | B31: 3
A32: Prezzo bombola 5kg IVA escl. (€) | B32: 24
A33: Costo CO2 totale 2025 con IVA (€) | B33: =B31*B32*1.22 -> 87.84
A34: Litri spillati 2025 (da vendite reali) | B34: ='Vendite 2025'!$J$23 -> 162.8
A35: Costo CO2 per litro (€) | B35: =B33/B34 -> 0.53955774
A36: PREVISIONE 2026
A37: Giornate 2025 | B37: 4
A38: Giornate 2026 (7: gio-dom + ven-dom) | B38: 7
A39: Fattore di scala (da litri previsti) | B39: =B40/B34 -> 1.8892301
A40: Litri spillati previsti 2026 | B40: ='Fabbisogno 2026'!$D$51+'Fabbisogno 2026'!$D$52+'Fabbisogno 2026'!$D$53+'Fabbisogno 2026'!$D$54 -> 307.56667
...

Sheet Vendite 2025
A1: Prodotto | B1: 28/08 | C1: 29/08 | D1: 30/08 | E1: 31/08 | F1: Totale Pezzi | G1: Prezzo Un. 2025 (€) | H1: Incasso (€) | I1: Litri alla spina per pezzo | J1: Litri Totali Spina
A2: ACQUA FRIZZANTE 0,5L | B2: 11 | C2: 11 | D2: 14 | E2: 26 | F2: =SUM(B2:E2) -> 62 | G2: 1 | H2: =F2*G2 -> 62 | J2: =IF(I2="","",F2*I2)
A3: ACQUA NATURALE 0,5L | B3: 31 | C3: 43 | D3: 47 | E3: 85 | F3: =SUM(B3:E3) -> 206 | G3: 1 | H3: =F3*G3 -> 206 | J3: =IF(I3="","",F3*I3)
A4: BIRRA BIONDA 0,2L | B4: 13 | C4: 13 | D4: 10 | E4: 30 | F4: =SUM(B4:E4) -> 66 | G4: 2.5 | H4: =F4*G4 -> 165 | I4: 0.2 | J4: =IF(I4="","",F4*I4) -> 13.2
A5: BIRRA BIONDA 0,4L | B5: 25 | C5: 34 | D5: 35 | E5: 77 | F5: =SUM(B5:E5) -> 171 | G5: 4 | H5: =F5*G5 -> 684 | I5: 0.4 | J5: =IF(I5="","",F5*I5) -> 68.4
A6: BIRRA ROSSA 0,2L | B6: 1 | C6: 1 | D6: 3 | E6: 10 | F6: =SUM(B6:E6) -> 15 | G6: 3 | H6: =F6*G6 -> 45 | I6: 0.2 | J6: =IF(I6="","",F6*I6) -> 3
A7: BIRRA ROSSA 0,4L | B7: 6 | C7: 7 | D7: 20 | E7: 20 | F7: =SUM(B7:E7) -> 53 | G7: 5 | H7: =F7*G7 -> 265 | I7: 0.4 | J7: =IF(I7="","",F7*I7) -> 21.2
A8: COCA COLA 0,2L | B8: 9 | C8: 11 | D8: 19 | E8: 32 | F8: =SUM(B8:E8) -> 71 | G8: 2 | H8: =F8*G8 -> 142 | I8: 0.2 | J8: =IF(I8="","",F8*I8) -> 14.2
A9: COCA COLA 0,4L | B9: 14 | C9: 19 | D9: 29 | E9: 28 | F9: =SUM(B9:E9) -> 90 | G9: 4 | H9: =F9*G9 -> 360 | I9: 0.4 | J9: =IF(I9="","",F9*I9) -> 36
A10: PATATINE FRITTE | B10: 52 | C10: 52 | D10: 99 | E10: 138 | F10: =SUM(B10:E10) -> 341 | G10: 3 | H10: =F10*G10 -> 1023 | J10: =IF(I10="","",F10*I10)
A11: PIADINA P.COTTO | B11: 10 | C11: 10 | D11: 16 | E11: 30 | F11: =SUM(B11:E11) -> 66 | G11: 5 | H11: =F11*G11 -> 330 | J11: =IF(I11="","",F11*I11)
A12: PIADINA P.COTTO E FORMAGGIO | B12: 28 | C12: 28 | D12: 22 | E12: 50 | F12: =SUM(B12:E12) -> 128 | G12: 5 | H12: =F12*G12 -> 640 | J12: =IF(I12="","",F12*I12)
A13: PIADINA P.CRUDO | B13: 20 | C13: 20 | D13: 8 | E13: 15 | F13: =SUM(B13:E13) -> 63 | G13: 5 | H13: =F13*G13 -> 315 | J13: =IF(I13="","",F13*I13)
A14: PIADINA P.CRUDO E FORMAGGIO | B14: 28 | C14: 28 | D14: 40 | E14: 37 | F14: =SUM(B14:E14) -> 133 | G14: 5 | H14: =F14*G14 -> 665 | J14: =IF(I14="","",F14*I14)
A15: PIADINA SALAME | B15: 3 | C15: 3 | D15: 8 | E15: 21 | F15: =SUM(B15:E15) -> 35 | G15: 5 | H15: =F15*G15 -> 175 | J15: =IF(I15="","",F15*I15)
A16: PIADINA SALAME E FORMAGGIO | B16: 17 | C16: 17 | D16: 27 | E16: 29 | F16: =SUM(B16:E16) -> 90 | G16: 5 | H16: =F16*G16 -> 450 | J16: =IF(I16="","",F16*I16)
A17: PIADINA SOLO FORMAGGIO | B17: 2 | C17: 2 | D17: 6 | E17: 5 | F17: =SUM(B17:E17) -> 15 | G17: 5 | H17: =F17*G17 -> 75 | J17: =IF(I17="","",F17*I17)
A18: SPRITZ APEROL | B18: 6 | C18: 7 | D18: 4 | E18: 5 | F18: =SUM(B18:E18) -> 22 | G18: 3.5 | H18: =F18*G18 -> 77 | I18: ='Prodotti Finiti'!$Q$9/1000 -> 0 | J18: =IF(I18="","",F18*I18) -> 0
A19: SPRITZ CAMPARI | B19: 2 | C19: 5 | D19: 3 | E19: 1 | F19: =SUM(B19:E19) -> 11 | G19: 3.5 | H19: =F19*G19 -> 38.5 | I19: ='Prodotti Finiti'!$Q$9/1000 -> 0 | J19: =IF(I19="","",F19*I19) -> 0
A20: THE LIMONE | B20: 5 | C20: 6 | D20: 8 | E20: 10 | F20: =SUM(B20:E20) -> 29 | G20: 2 | H20: =F20*G20 -> 58 | J20: =IF(I20="","",F20*I20)
A21: THE PESCA | B21: 7 | C21: 7 | D21: 21 | E21: 13 | F21: =SUM(B21:E21) -> 48 | G21: 2 | H21: =F21*G21 -> 96 | J21: =IF(I21="","",F21*I21)
A22: VINO BIANCO 0,2L | B22: 11 | C22: 13 | D22: 5 | E22: 5 | F22: =SUM(B22:E22) -> 34 | G22: 2.5 | H22: =F22*G22 -> 85 | I22: 0.2 | J22: =IF(I22="","",F22*I22) -> 6.8
A23: TOTALE | F23: =SUM(F2:F22) -> 1749 | H23: =SUM(H2:H22) -> 5956.5 | J23: =SUM(J2:J22) -> 162.8
A25: Fonte: Report vendite SAGRA SANT-AGOSTINO 28-31/08/2025 (4 giornate). 'Litri alla spina' considera solo birra, coca premix e vino da fusto (spritz: solo la quota vino).

Sheet Modello Hamburger
A1: MODELLO COMBO HAMBURGER + PATATINE - fornitore con costo fisso a serata
A3: DATI DA CONTRATTARE (celle gialle)
A4: Costo fornitore per hamburger (€) | B4: 4
A5: Costo fisso per serata (€) | B5: 120
A6: Serate con hamburger | B6: 7
A7: Combo vendute in totale | B7: 400
A8: Prezzo di vendita combo (€) | B8: 9.5
A9: COSTO VARIABILE PER PEZZO
A10: Fornitore (carne, cottura, verdure) | B10: =B4 -> 4
A11: Pagnottina | B11: ='Prezzi Unitari'!$E$10 -> 0.3146
A12: Formaggio | B12: =Parametri!$B$48/100*'Prezzi Unitari'!$E$7 -> 0.14476
A13: Patatine surgelate | B13: =Parametri!$B$78/1000*'Materie Prime IperTosano'!$H$4 -> 0.312
A14: Olio di frittura | B14: =Parametri!$B$78*Parametri!$B$79/0.92/1000*'Prezzi Unitari'!$E$2 -> 0.062458696
A15: Ketchup + maionese | B15: =Parametri!$B$82*'Prezzi Unitari'!$E$3+Parametri!$B$83*'Prezzi Unitari'!$E$4 -> 0.37339394
A16: Stecchini | B16: =Parametri!$B$84*'Prezzi Unitari'!$E$13 -> 0.060024
A17: Piatti | B17: =Parametri!$B$80*'Prezzi Unitari'!$E$12 -> 0.117608
A18: Tovaglioli | B18: =Parametri!$B$81*'Prezzi Unitari'!$E$11 -> 0.067622857
A19: COSTO VARIABILE TOTALE | B19: =SUM(B10:B18) -> 5.4524675
A21: RISULTATO ECONOMICO
A22: Margine di contribuzione per pezzo (€) | B22: =B8-B19 -> 4.0475325
A23: Costi fissi totali (€) | B23: =B5*B6 -> 840
A24: Ricavo totale (€) | B24: =B7*B8 -> 3800
A25: Costi variabili totali (€) | B25: =B7*B19 -> 2180.987
A26: UTILE (€) | B26: =B24-B25-B23 -> 779.013
A27: Margine sul ricavo (%) | B27: =IF(B24=0,"",B26/B24) -> 0.20500342
A28: PAREGGIO: combo da vendere | B28: =IF(B22<=0,"mai",ROUNDUP(B23/B22,0)) -> 208
A29: TENUTA PER SINGOLA SERATA (proiezione dai volumi 2025) | B29: =IF(B22<=0,"mai",ROUNDUP(B5/B22,0)) -> 30
A30: Serata | B30: Peso sulle vendite 2025 | C30: Hamburger stimati | D30: Margine di contribuzione (€) | E30: Costo fisso (€) | F30: Risultato serata (€)
A31: WE1 giovedi | B31: 0.097365512 | C31: =ROUND($B$7*B31,0) -> 39 | D31: =C31*$B$22 -> 157.85377 | E31: =$B$5 -> 120 | F31: =D31-E31 -> 37.853768
A32: WE1 venerdi | B32: 0.10639278 | C32: =ROUND($B$7*B32,0) -> 43 | D32: =C32*$B$22 -> 174.0439 | E32: =$B$5 -> 120 | F32: =D32-E32 -> 54.043898
A33: WE1 sabato | B33: 0.13964628 | C33: =ROUND($B$7*B33,0) -> 56 | D33: =C33*$B$22 -> 226.66182 | E33: =$B$5 -> 120 | F33: =D33-E33 -> 106.66182
A34: WE1 domenica | B34: 0.20527819 | C34: =ROUND($B$7*B34,0) -> 82 | D34: =C34*$B$22 -> 331.89767 | E34: =$B$5 -> 120 | F34: =D34-E34 -> 211.89767
A35: WE2 venerdi | B35: 0.10639278 | C35: =ROUND($B$7*B35,0) -> 43 | D35: =C35*$B$22 -> 174.0439 | E35: =$B$5 -> 120 | F35: =D35-E35 -> 54.043898
A36: WE2 sabato | B36: 0.13964628 | C36: =ROUND($B$7*B36,0) -> 56 | D36: =C36*$B$22 -> 226.66182 | E36: =$B$5 -> 120 | F36: =D36-E36 -> 106.66182
A37: WE2 domenica | B37: 0.20527819 | C37: =ROUND($B$7*B37,0) -> 82 | D37: =C37*$B$22 -> 331.89767 | E37: =$B$5 -> 120 | F37: =D37-E37 -> 211.89767
A38: TOTALE | C38: =SUM(C31:C37) -> 401 | D38: =SUM(D31:D37) -> 1623.0605 | E38: =SUM(E31:E37) -> 840 | F38: =SUM(F31:F37) -> 783.06054
A40: SCENARI DI PREZZO E VOLUME (utile in €)
A41: Prezzo \ Pezzi venduti | B41: 250 | C41: 300 | D41: 350 | E41: 400 | F41: 450
A42: 8.5 | B42: =(B$41*$A42)-(B$41*$B$19)-($B$5*$B$6) -> -78.116873 | C42: =(C$41*$A42)-(C$41*$B$19)-($B$5*$B$6) -> 74.259752 | D42: =(D$41*$A42)-(D$41*$B$19)-($B$5*$B$6) -> 226.63638 | E42: =(E$41*$A42)-(E$41*$B$19)-($B$5*$B$6) -> 379.013 | F42: =(F$41*$A42)-(F$41*$B$19)-($B$5*$B$6) -> 531.38963
A43: 9 | B43: =(B$41*$A43)-(B$41*$B$19)-($B$5*$B$6) -> 46.883127 | C43: =(C$41*$A43)-(C$41*$B$19)-($B$5*$B$6) -> 224.25975 | D43: =(D$41*$A43)-(D$41*$B$19)-($B$5*$B$6) -> 401.63638 | E43: =(E$41*$A43)-(E$41*$B$19)-($B$5*$B$6) -> 579.013 | F43: =(F$41*$A43)-(F$41*$B$19)-($B$5*$B$6) -> 756.38963
...

Sheet Valutazione Nuovi Fritti
A1: VALUTAZIONE - prodotti non ancora inseriti nel menu
A3: PARAMETRI PORZIONE
A4: Parametro | B4: Anelli di cipolla | C4: Olive ascolane
A5: Grammi per porzione | B5: 120 | C5: 150
A6: Olio assorbito (% del peso) | B6: 0.1 | C6: 0.1
A7: N. piatti | B7: 1 | C7: 1
A8: N. tovaglioli | B8: 1 | C8: 1
A9: N. bustine ketchup | B9: 1 | C9: 0
A10: N. bustine maionese | B10: 1 | C10: 1
A11: N. stecchini | B11: 2 | C11: 2
A13: COSTO PER PORZIONE
A14: Voce di costo | B14: Anelli di cipolla | C14: Olive ascolane
A15: Prodotto surgelato | B15: =B5/1000*'Materie Prime IperTosano'!$H$6 -> 0.825 | C15: =C5/1000*'Materie Prime IperTosano'!$H$7 -> 0.987
A16: Olio di frittura | B16: =B5*B6/0.92/1000*'Prezzi Unitari'!$E$2 -> 0.037475217 | C16: =C5*C6/0.92/1000*'Prezzi Unitari'!$E$2 -> 0.046844022
A17: Ketchup + maionese | B17: =B9*'Prezzi Unitari'!$E$3+B10*'Prezzi Unitari'!$E$4 -> 0.18669697 | C17: =C9*'Prezzi Unitari'!$E$3+C10*'Prezzi Unitari'!$E$4 -> 0.093810606
A18: Piatto | B18: =B7*'Prezzi Unitari'!$E$12 -> 0.058804 | C18: =C7*'Prezzi Unitari'!$E$12 -> 0.058804
A19: Tovagliolo | B19: =B8*'Prezzi Unitari'!$E$11 -> 0.033811429 | C19: =C8*'Prezzi Unitari'!$E$11 -> 0.033811429
A20: Stecchini | B20: =B11*'Prezzi Unitari'!$E$13 -> 0.040016 | C20: =C11*'Prezzi Unitari'!$E$13 -> 0.040016
A21: COSTO TOTALE | B21: =SUM(B15:B20) -> 1.1818036 | C21: =SUM(C15:C20) -> 1.2602861
A23: MARGINE AI VARI PREZZI DI VENDITA
A24: Prezzo di vendita | B24: Anelli: margine € | C24: Anelli: margine % | D24: Olive: margine € | E24: Olive: margine %
A25: 3 | B25: =$A25-$B$21 -> 1.8181964 | C25: =B25/$A25 -> 0.60606546 | D25: =$A25-$C$21 -> 1.7397139 | E25: =D25/$A25 -> 0.57990465
A26: 3.5 | B26: =$A26-$B$21 -> 2.3181964 | C26: =B26/$A26 -> 0.66234182 | D26: =$A26-$C$21 -> 2.2397139 | E26: =D26/$A26 -> 0.63991827
A27: 4 | B27: =$A27-$B$21 -> 2.8181964 | C27: =B27/$A27 -> 0.7045491 | D27: =$A27-$C$21 -> 2.7397139 | E27: =D27/$A27 -> 0.68492849
A28: 4.5 | B28: =$A28-$B$21 -> 3.3181964 | C28: =B28/$A28 -> 0.73737697 | D28: =$A28-$C$21 -> 3.2397139 | E28: =D28/$A28 -> 0.71993643
A29: 5 | B29: =$A29-$B$21 -> 3.8181964 | C29: =B29/$A29 -> 0.76363928 | D29: =$A29-$C$21 -> 3.7397139 | E29: =D29/$A29 -> 0.74794279
A31: Confronto: le patatine fritte costano 0,69 € e si vendono a 3,00 € (77% di margine).
A32: Prezzi IperTosano gia' IVA inclusa. Grammature per porzione da verificare: sono stime.
A33: Questi due prodotti NON sono nel foglio 'Prodotti Finiti' ne' nel menu HTML.
